<?xml version="1.0" ?>
<sdf version="1.9">
    <world name="car_world">
        <physics name="1ms" type="ode">
            <max_step_size>0.001</max_step_size>
            <real_time_factor>1.0</real_time_factor>
        </physics>
        <plugin
            filename="libignition-gazebo-physics-system.so"
            name="ignition::gazebo::systems::Physics">
        </plugin>
        <plugin
            filename="libignition-gazebo-user-commands-system.so"
            name="ignition::gazebo::systems::UserCommands">
        </plugin>
        <plugin
            filename="libignition-gazebo-scene-broadcaster-system.so"
            name="ignition::gazebo::systems::SceneBroadcaster">
        </plugin>
        <!-- Moving Forward-->
        <plugin filename="libignition-gazebo-triggered-publisher-system.so"
                name="ignition::gazebo::systems::TriggeredPublisher">
            <input type="ignition.msgs.Int32" topic="/keyboard/keypress">
            <!--up arrow key-->
                <match field="data">16777235</match>
            </input>
            <output type="ignition.msgs.Twist" topic="/cmd_vel">
                linear: {x: 0.5}, angular: {z: 0.0}
            </output>
        </plugin>
        <!-- Moving Backward-->
        <plugin filename="libignition-gazebo-triggered-publisher-system.so"
                name="ignition::gazebo::systems::TriggeredPublisher">
            <input type="ignition.msgs.Int32" topic="/keyboard/keypress">
            <!--down arrow key-->
                <match field="data">16777237</match>
            </input>
            <output type="ignition.msgs.Twist" topic="/cmd_vel">
                linear: {x: -0.5}, angular: {z: 0.0}
            </output>
        </plugin>
        <!-- Moving Left-->
        <plugin filename="libignition-gazebo-triggered-publisher-system.so"
                name="ignition::gazebo::systems::TriggeredPublisher">
            <input type="ignition.msgs.Int32" topic="/keyboard/keypress">
            <!--left arrow key-->
                <match field="data">16777234</match>
            </input>
            <output type="ignition.msgs.Twist" topic="/cmd_vel">
                linear: {x: 0.0}, angular: {z: 1.0}
            </output>
        </plugin>
        <!-- Moving Right-->
        <plugin filename="libignition-gazebo-triggered-publisher-system.so"
                name="ignition::gazebo::systems::TriggeredPublisher">
            <input type="ignition.msgs.Int32" topic="/keyboard/keypress">
            <!--right arrow key-->
                <match field="data">16777236</match>
            </input>
            <output type="ignition.msgs.Twist" topic="/cmd_vel">
                linear: {x: 0.0}, angular: {z: -1.0}
            </output>
        </plugin>

        <light type="directional" name="sun">
            <cast_shadows>true</cast_shadows>
            <pose>0 0 10 0 0 0</pose>
            <diffuse>0.8 0.8 0.8 1</diffuse>
            <specular>0.2 0.2 0.2 1</specular>
            <attenuation>
                <range>1000</range>
                <constant>0.9</constant>
                <linear>0.01</linear>
                <quadratic>0.001</quadratic>
            </attenuation>
            <direction>-0.5 0.1 -0.9</direction>
        </light>

        <model name="ground_plane">
            <static>true</static>
            <link name="link">
                <collision name="collision">
                <geometry>
                    <plane>
                    <normal>0 0 1</normal>
                    </plane>
                </geometry>
                </collision>
                <visual name="visual">
                <geometry>
                    <plane>
                    <normal>0 0 1</normal>
                    <size>100 100</size>
                    </plane>
                </geometry>
                <material>
                    <ambient>0.8 0.8 0.8 1</ambient>
                    <diffuse>0.8 0.8 0.8 1</diffuse>
                    <specular>0.8 0.8 0.8 1</specular>
                </material>
                </visual>
            </link>
        </model>

        <model name='maze'>
            <static>true</static>
            <pose relative_to='world'>0 0 0 0 0 0</pose>
            <link name='wall_1'>
                <pose relative_to='__model__'>-9.5 0 0 0 0 0</pose>
            <inertial> <!--inertial properties of the link mass, inertia matrix-->
                <mass>1.14395</mass>
                <inertia>
                    <ixx>0.095329</ixx>
                    <ixy>0</ixy>
                    <ixz>0</ixz>
                    <iyy>0.381317</iyy>
                    <iyz>0</iyz>
                    <izz>0.476646</izz>
                </inertia>
            </inertial>
            <visual name='visual'>
                <geometry>
                    <box>
                        <size>1.0 20 4</size>
                    </box>
                </geometry>
                <!--let's add color to our link-->
                <material>
                    <ambient>0.0 0.0 1.0 1</ambient>
                    <diffuse>0.0 0.0 1.0 1</diffuse>
                    <specular>0.0 0.0 1.0 1</specular>
                </material>
            </visual>
            <collision name='collision'>
                    <geometry>
                        <box>
                            <size>1.0 20 4</size>
                        </box>
                    </geometry>
                </collision>
            </link>

            <link name='wall_2'>
                <pose relative_to='__model__'>-5.5 -2.5 0 0 0 0</pose>
            <inertial> <!--inertial properties of the link mass, inertia matrix-->
                <mass>1.14395</mass>
                <inertia>
                    <ixx>0.095329</ixx>
                    <ixy>0</ixy>
                    <ixz>0</ixz>
                    <iyy>0.381317</iyy>
                    <iyz>0</iyz>
                    <izz>0.476646</izz>
                </inertia>
            </inertial>
            <visual name='visual'>
                <geometry>
                    <box>
                        <size>1.0 15 4</size>
                    </box>
                </geometry>
                <!--let's add color to our link-->
                <material>
                    <ambient>0.0 0.0 1.0 1</ambient>
                    <diffuse>0.0 0.0 1.0 1</diffuse>
                    <specular>0.0 0.0 1.0 1</specular>
                </material>
            </visual>
            <collision name='collision'>
                    <geometry>
                        <box>
                            <size>1.0 15 4</size>
                        </box>
                    </geometry>
                </collision>
            </link>

            <link name='wall_3'>
                <pose relative_to='__model__'>0 10 0 0 0 1.5708</pose>
            <inertial> <!--inertial properties of the link mass, inertia matrix-->
                <mass>1.14395</mass>
                <inertia>
                    <ixx>0.095329</ixx>
                    <ixy>0</ixy>
                    <ixz>0</ixz>
                    <iyy>0.381317</iyy>
                    <iyz>0</iyz>
                    <izz>0.476646</izz>
                </inertia>
            </inertial>
            <visual name='visual'>
                <geometry>
                    <box>
                        <size>1.0 20 4</size>
                    </box>
                </geometry>
                <!--let's add color to our link-->
                <material>
                    <ambient>0.0 0.0 1.0 1</ambient>
                    <diffuse>0.0 0.0 1.0 1</diffuse>
                    <specular>0.0 0.0 1.0 1</specular>
                </material>
            </visual>
            <collision name='collision'>
                    <geometry>
                        <box>
                            <size>1.0 20 4</size>
                        </box>
                    </geometry>
                </collision>
            </link>

            <link name='wall_4'>
                <pose relative_to='__model__'>-3.5 5.5 0 0 0 1.5708</pose>
            <inertial> <!--inertial properties of the link mass, inertia matrix-->
                <mass>1.14395</mass>
                <inertia>
                    <ixx>0.095329</ixx>
                    <ixy>0</ixy>
                    <ixz>0</ixz>
                    <iyy>0.381317</iyy>
                    <iyz>0</iyz>
                    <izz>0.476646</izz>
                </inertia>
            </inertial>
            <visual name='visual'>
                <geometry>
                    <box>
                        <size>1.0 5 4</size>
                    </box>
                </geometry>
                <!--let's add color to our link-->
                <material>
                    <ambient>0.0 0.0 1.0 1</ambient>
                    <diffuse>0.0 0.0 1.0 1</diffuse>
                    <specular>0.0 0.0 1.0 1</specular>
                </material>
            </visual>
            <collision name='collision'>
                    <geometry>
                        <box>
                            <size>1.0 5 4</size>
                        </box>
                    </geometry>
                </collision>
            </link>

            <link name='wall_5'>
                <pose relative_to='__model__'>-0.5 1 0 0 0 0</pose>
            <inertial> <!--inertial properties of the link mass, inertia matrix-->
                <mass>1.14395</mass>
                <inertia>
                    <ixx>0.095329</ixx>
                    <ixy>0</ixy>
                    <ixz>0</ixz>
                    <iyy>0.381317</iyy>
                    <iyz>0</iyz>
                    <izz>0.476646</izz>
                </inertia>
            </inertial>
            <visual name='visual'>
                <geometry>
                    <box>
                        <size>1.0 10 4</size>
                    </box>
                </geometry>
                <!--let's add color to our link-->
                <material>
                    <ambient>0.0 0.0 1.0 1</ambient>
                    <diffuse>0.0 0.0 1.0 1</diffuse>
                    <specular>0.0 0.0 1.0 1</specular>
                </material>
            </visual>
            <collision name='collision'>
                    <geometry>
                        <box>
                            <size>1.0 10 4</size>
                        </box>
                    </geometry>
                </collision>
            </link>

            <link name='wall_6'>
                <pose relative_to='__model__'>4.5 -4.5 0 0 0 1.5708</pose>
            <inertial> <!--inertial properties of the link mass, inertia matrix-->
                <mass>1.14395</mass>
                <inertia>
                    <ixx>0.095329</ixx>
                    <ixy>0</ixy>
                    <ixz>0</ixz>
                    <iyy>0.381317</iyy>
                    <iyz>0</iyz>
                    <izz>0.476646</izz>
                </inertia>
            </inertial>
            <visual name='visual'>
                <geometry>
                    <box>
                        <size>1.0 11 4</size>
                    </box>
                </geometry>
                <!--let's add color to our link-->
                <material>
                    <ambient>0.0 0.0 1.0 1</ambient>
                    <diffuse>0.0 0.0 1.0 1</diffuse>
                    <specular>0.0 0.0 1.0 1</specular>
                </material>
            </visual>
            <collision name='collision'>
                    <geometry>
                        <box>
                            <size>1.0 11 4</size>
                        </box>
                    </geometry>
                </collision>
            </link>

            <link name='wall_7'>
                <pose relative_to='__model__'>4 5 0 0 0 0</pose>
            <inertial> <!--inertial properties of the link mass, inertia matrix-->
                <mass>1.14395</mass>
                <inertia>
                    <ixx>0.095329</ixx>
                    <ixy>0</ixy>
                    <ixz>0</ixz>
                    <iyy>0.381317</iyy>
                    <iyz>0</iyz>
                    <izz>0.476646</izz>
                </inertia>
            </inertial>
            <visual name='visual'>
                <geometry>
                    <box>
                        <size>1.0 10 4</size>
                    </box>
                </geometry>
                <!--let's add color to our link-->
                <material>
                    <ambient>0.0 0.0 1.0 1</ambient>
                    <diffuse>0.0 0.0 1.0 1</diffuse>
                    <specular>0.0 0.0 1.0 1</specular>
                </material>
            </visual>
            <collision name='collision'>
                    <geometry>
                        <box>
                            <size>1.0 10 4</size>
                        </box>
                    </geometry>
                </collision>
            </link>

            <link name='wall_8'>
                <pose relative_to='__model__'>10 0 0 0 0 0</pose>
            <inertial> <!--inertial properties of the link mass, inertia matrix-->
                <mass>1.14395</mass>
                <inertia>
                    <ixx>0.095329</ixx>
                    <ixy>0</ixy>
                    <ixz>0</ixz>
                    <iyy>0.381317</iyy>
                    <iyz>0</iyz>
                    <izz>0.476646</izz>
                </inertia>
            </inertial>
            <visual name='visual'>
                <geometry>
                    <box>
                        <size>1.0 10 4</size>
                    </box>
                </geometry>
                <!--let's add color to our link-->
                <material>
                    <ambient>0.0 0.0 1.0 1</ambient>
                    <diffuse>0.0 0.0 1.0 1</diffuse>
                    <specular>0.0 0.0 1.0 1</specular>
                </material>
            </visual>
            <collision name='collision'>
                    <geometry>
                        <box>
                            <size>1.0 10 4</size>
                        </box>
                    </geometry>
                </collision>
            </link>
        </model>

        <model name='Ed_Robot' canonical_link='chassis'>
            <pose relative_to='world'>-7.5 -7 0 0 0 3.14159</pose>

            <!--chassis-->
            <link name='chassis'>
                <pose relative_to='__model__'>0 0 0 0 0 0</pose>
            <inertial> <!--inertial properties of the link mass, inertia matix-->
                <mass>1.14395</mass>
                <inertia>
                    <ixx>0.095329</ixx>
                    <ixy>0</ixy>
                    <ixz>0</ixz>
                    <iyy>0.381317</iyy>
                    <iyz>0</iyz>
                    <izz>0.476646</izz>
                </inertia>
            </inertial>
            <visual name='visual'>
                <geometry>
                    <mesh>
                        <uri>meshes/chassis.dae</uri>
                        <scale>0.01 0.01 0.01</scale>
                    </mesh>
                </geometry>
            </visual>
            <collision name='collision'>
                <geometry>
                    <mesh>
                        <uri>meshes/chassis.dae</uri>
                        <scale>0.01 0.01 0.01</scale>
                    </mesh>
                </geometry>
            </collision>
            <frame name="lidar_frame" attached_to='chassis'>
                <pose>0 0 0 0 0 0</pose>
            </frame>
            <frame name="tof_frame" attached_to='chassis'>
                <pose>0 0 0 0 0 0</pose>
            </frame>

            <!-- Camera -->
            <sensor name="camera_sensor" type="camera">
                <pose relative_to="chassis">0.12521 0 1 0 0 0</pose> <!-- Adjust position and orientation -->
                <topic>camera/image</topic>
                <update_rate>30</update_rate>
                <camera>
                    <horizontal_fov>1.326</horizontal_fov> <!-- Field of view in radians -->
                    <image>
                        <width>2028</width> <!-- Image width -->
                        <height>1520</height> <!-- Image height -->
                        <format>R8G8B8</format> <!-- Image format -->
                    </image>
                    <clip>
                        <near>0.1</near> <!-- Near clipping distance -->
                        <far>100</far> <!-- Far clipping distance -->
                    </clip>
                </camera>
                <always_on>true</always_on>
                <visualize>true</visualize>
            </sensor>

            <!-- ToF Sensor front -->
            <sensor name="tof_front" type="gpu_lidar">
                <pose relative_to='tof_frame'>0 -1.4 0.4 0 0 -1.57079632</pose> 
                <topic>tof/front</topic>
                <update_rate>30</update_rate>
                <ray>
                    <scan>
                        <horizontal>
                            <samples>1</samples>
                            <resolution>1</resolution>
                            <min_angle>0</min_angle>
                            <max_angle>0</max_angle>
                        </horizontal>
                        <vertical>
                            <samples>1</samples>
                            <resolution>1</resolution>
                            <min_angle>0</min_angle>
                            <max_angle>0</max_angle>
                        </vertical>
                    </scan>
                    <range>
                        <min>0.01</min>
                        <max>10.0</max>
                        <resolution>0.01</resolution>
                    </range>
                </ray>
                <always_on>1</always_on>
                <visualize>true</visualize>
            </sensor>

            <!-- ToF Sensor back -->
            <sensor name="tof_back" type="gpu_lidar">
                <pose relative_to='tof_frame'>0 1.2 0.4 0 0 1.57079632</pose>
                <topic>tof/back</topic>
                <update_rate>30</update_rate>
                <ray>
                    <scan>
                        <horizontal>
                            <samples>1</samples>
                            <resolution>1</resolution>
                            <min_angle>0</min_angle>
                            <max_angle>0</max_angle>
                        </horizontal>
                        <vertical>
                            <samples>1</samples>
                            <resolution>1</resolution>
                            <min_angle>0</min_angle>
                            <max_angle>0</max_angle>
                        </vertical>
                    </scan>
                    <range>
                        <min>0.01</min>
                        <max>10.0</max>
                        <resolution>0.01</resolution>
                    </range>
                </ray>
                <always_on>1</always_on>
                <visualize>true</visualize>
            </sensor>

            <!-- ToF Sensor down -->
            <sensor name="tof_down" type="gpu_lidar">
                <pose relative_to='tof_frame'>0 -1.5 0.53 0 1.57079632 -1.57079632</pose> 
                <topic>tof/down</topic>
                <update_rate>30</update_rate>
                <ray>
                    <scan>
                        <horizontal>
                            <samples>1</samples>
                            <resolution>1</resolution>
                            <min_angle>0</min_angle>
                            <max_angle>0</max_angle>
                        </horizontal>
                        <vertical>
                            <samples>1</samples>
                            <resolution>1</resolution>
                            <min_angle>0</min_angle>
                            <max_angle>0</max_angle>
                        </vertical>
                    </scan>
                    <range>
                        <min>0.01</min>
                        <max>10.0</max>
                        <resolution>0.01</resolution>
                    </range>
                </ray>
                <always_on>1</always_on>
                <visualize>true</visualize>
            </sensor>

            <sensor name='gpu_lidar' type='gpu_lidar'>"
                <pose relative_to='lidar_frame'>0 1.12 1.29 0 0 -1.571</pose>
                <topic>lidar</topic>
                <update_rate>10</update_rate>
                <ray>
                    <scan>
                        <horizontal>
                            <samples>100</samples>
                            <resolution>1</resolution>
                            <min_angle>0</min_angle>
                            <max_angle>6.283185</max_angle>
                        </horizontal>
                        <vertical>
                            <samples>1</samples>
                            <resolution>0.01</resolution>
                            <min_angle>0</min_angle>
                            <max_angle>0</max_angle>
                        </vertical>
                    </scan>
                    <range>
                        <min>0.08</min>
                        <max>10.0</max>
                        <resolution>0.01</resolution>
                    </range>
                </ray>
                <always_on>1</always_on>
                <visualize>true</visualize>
            </sensor>

                <sensor name="imu_sensor" type="imu">
                    <always_on>true</always_on>
                    <update_rate>1</update_rate>
                    <pose>0 0 0 0 0 0</pose>
                    <visualize>true</visualize>
                    <topic>imu</topic>
                </sensor>
            </link>

            <!--back left wheel-->
            <link name='back_left_wheel'>
                <pose relative_to="chassis">0.86 0.97 0.44 0 0 0</pose>
                <inertial>
                    <mass>1</mass>
                    <inertia>
                        <ixx>0.043333</ixx>
                        <ixy>0</ixy>
                        <ixz>0</ixz>
                        <iyy>0.043333</iyy>
                        <iyz>0</iyz>
                        <izz>0.08</izz>
                    </inertia>
                </inertial>
                <visual name='visual'>
                    <geometry>
                        <mesh>
                            <uri>meshes/back_left_wheel.dae</uri>
                            <scale>0.01 0.01 0.01</scale>
                        </mesh>
                    </geometry>
                </visual>
                <collision name='collision'>
                    <geometry>
                        <mesh>
                            <uri>meshes/back_left_wheel.dae</uri>
                            <scale>0.01 0.01 0.01</scale>
                        </mesh>
                    </geometry>
                </collision>
            </link>

            <!--back right wheel-->
            <link name='back_right_wheel'>
                <pose relative_to="chassis">-0.86 0.97 0.44 0 0 0</pose>
                <inertial>
                    <mass>1</mass>
                    <inertia>
                        <ixx>0.043333</ixx>
                        <ixy>0</ixy>
                        <ixz>0</ixz>
                        <iyy>0.043333</iyy>
                        <iyz>0</iyz>
                        <izz>0.08</izz>
                    </inertia>
                </inertial>
                <visual name='visual'>
                    <geometry>
                        <mesh>
                            <uri>meshes/back_right_wheel.dae</uri>
                            <scale>0.01 0.01 0.01</scale>
                        </mesh>
                    </geometry>
                </visual>
                <collision name='collision'>
                    <geometry>
                        <mesh>
                            <uri>meshes/back_right_wheel.dae</uri>
                            <scale>0.01 0.01 0.01</scale>
                        </mesh>
                    </geometry>
                </collision>
            </link>

            <!--front left wheel-->
            <link name='front_left_wheel'>
                <pose relative_to="chassis">0.86 -1.26 0.44 0 0 0</pose>
                <inertial>
                    <mass>1</mass>
                    <inertia>
                        <ixx>0.043333</ixx>
                        <ixy>0</ixy>
                        <ixz>0</ixz>
                        <iyy>0.043333</iyy>
                        <iyz>0</iyz>
                        <izz>0.08</izz>
                    </inertia>
                </inertial>
                <visual name='visual'>
                    <geometry>
                        <mesh>
                            <uri>meshes/front_left_wheel.dae</uri>
                            <scale>0.01 0.01 0.01</scale>
                        </mesh>
                    </geometry>
                </visual>
                <collision name='collision'>
                    <geometry>
                        <mesh>
                            <uri>meshes/front_left_wheel.dae</uri>
                            <scale>0.01 0.01 0.01</scale>
                        </mesh>
                    </geometry>
                </collision>
            </link>

            <!--front right wheel-->
            <link name='front_right_wheel'>
                <pose relative_to="chassis">-0.86 -1.26 0.44 0 0 0</pose>
                <inertial>
                    <mass>1</mass>
                    <inertia>
                        <ixx>0.043333</ixx>
                        <ixy>0</ixy>
                        <ixz>0</ixz>
                        <iyy>0.043333</iyy>
                        <iyz>0</iyz>
                        <izz>0.08</izz>
                    </inertia>
                </inertial>
                <visual name='visual'>
                    <geometry>
                        <mesh>
                            <uri>meshes/front_right_wheel.dae</uri>
                            <scale>0.01 0.01 0.01</scale>
                        </mesh>
                    </geometry>
                </visual>
                <collision name='collision'>
                    <geometry>
                        <mesh>
                            <uri>meshes/front_right_wheel.dae</uri>
                            <scale>0.01 0.01 0.01</scale>
                        </mesh>
                    </geometry>
                </collision>
            </link>

            <joint name='back_left_wheel_joint' type='revolute'>
                <pose relative_to='back_left_wheel'/>
                <parent>chassis</parent>
                <child>back_left_wheel</child>
                <axis>
                    <xyz expressed_in='__model__'>1 0 0</xyz>
                    <limit>
                        <lower>-1.79769e+308</lower>    
                    </limit>
                </axis>
            </joint>

            <joint name='back_right_wheel_joint' type='revolute'>
                <pose relative_to='back_right_wheel'/>
                <parent>chassis</parent>
                <child>back_right_wheel</child>
                <axis>
                    <xyz expressed_in='__model__'>1 0 0</xyz>
                    <limit>
                        <lower>-1.79769e+308</lower>    
                    </limit>
                </axis>
            </joint>

            <!--front left wheel joint-->
            <joint name='front_left_wheel_joint' type='revolute'>
                <pose relative_to='front_left_wheel'/>
                <parent>chassis</parent>
                <child>front_left_wheel</child>
                <axis>
                    <xyz expressed_in='__model__'>1 0 0</xyz>
                    <limit>
                        <lower>-1.79769e+308</lower>    <!--negative infinity-->
                        <upper>1.79769e+308</upper>     <!--positive infinity-->
                    </limit>
                </axis>
            </joint>

            <!--front right wheel joint-->
            <joint name='front_right_wheel_joint' type='revolute'>
                <pose relative_to='front_right_wheel'/>
                <parent>chassis</parent>
                <child>front_right_wheel</child>
                <axis>
                    <xyz expressed_in='__model__'>1 0 0</xyz>
                    <limit>
                        <lower>-1.79769e+308</lower>    <!--negative infinity-->
                        <upper>1.79769e+308</upper>     <!--positive infinity-->
                    </limit>
                </axis>
            </joint>

            <plugin
                filename="libignition-gazebo-diff-drive-system.so"
                name="ignition::gazebo::systems::DiffDrive">
                <left_joint>front_left_wheel_joint</left_joint>
                <right_joint>front_right_wheel_joint</right_joint>
                <left_joint>back_left_wheel_joint</left_joint>
                <right_joint>back_right_wheel_joint</right_joint>
                <wheel_separation>1.72</wheel_separation>
                <wheel_radius>0.1</wheel_radius>
                <odom_publish_frequency>1</odom_publish_frequency>
                <topic>cmd_vel</topic>
                <!-- <min_velocity>-10</min_velocity>
                <max_velocity>10</max_velocity> -->
            </plugin>

            <plugin
                filename="libignition-gazebo-imu-system.so"
                name="ignition::gazebo::systems::Imu">
            </plugin>

            <plugin
                filename="gz-sim-sensors-system"
                name="gz::sim::systems::Sensors">
                <render_engine>ogre2</render_engine>
            </plugin>

            <plugin
                filename="libignition-gazebo-joint-velocity-system.so"
                name="ignition::gazebo::systems::JointVelocity">
                <joint_name>front_left_wheel_joint</joint_name>
                <topic>front_left_wheel/velocity</topic>
            </plugin>

            <plugin
                filename="libignition-gazebo-joint-velocity-system.so"
                name="ignition::gazebo::systems::JointVelocity">
                <joint_name>front_right_wheel_joint</joint_name>
                <topic>front_right_wheel/velocity</topic>
            </plugin>

            <plugin
                filename="libignition-gazebo-joint-velocity-system.so"
                name="ignition::gazebo::systems::JointVelocity">
                <joint_name>back_left_wheel_joint</joint_name>
                <topic>back_left_wheel/velocity</topic>
            </plugin>

            <plugin
                filename="libignition-gazebo-joint-velocity-system.so"
                name="ignition::gazebo::systems::JointVelocity">
                <joint_name>back_right_wheel_joint</joint_name>
                <topic>back_right_wheel/velocity</topic>
            </plugin>

            <plugin
                name="ignition::gazebo::systems::OdometryPublisher"
                filename="libignition-gazebo6-odometry-publisher-system.so">
                <odom_publish_frequency>50</odom_publish_frequency>
                <publish_tf>true</publish_tf>
                <odom_frame>odom</odom_frame>
                <child_frame>base_link</child_frame>
                <velocity_smoothing_factor>0.1</velocity_smoothing_factor>
            </plugin>

        </model>
    </world>
</sdf>